Workbook

Sheet Input
A1: Option - 1 | B1: Lease Property
A2: Start date | B2: 45748
A3: No. of days in a year | B3: 365
A4: Property Value | B4: 45000000
A5: Land size | B5: 3000 | C5: Sq.Ft.
A6: Building | B6: 2400 | C6: Sq.Ft.
A7: Rental yield | B7: 0.05
A8: Increase in Rental yield | B8: 0.08
A9: Capital Appreciation of Property | B9: 0.13
A10: Rent Deposit(Non Refundable) | B10: 5000000
A11: FD rate | B11: 0.06
A12: Income Tax | B12: 0.2517
A14: Option - 2 | B14: Mc Donald's Franchise
A15: Start date | B15: 45748
A16: No. of days in a year | B16: 365
A18: Franchise cost | B18: 3000000
A19: Furniture | B19: 1100000
A20: Development Cost | B20: 5000000
A21: Interiors cost | B21: 2000000
A22: Civil work | B22: 1000000
A23: Machinery | B23: 3500000
A24: Total | B24: =SUM(B18:B23) -> 15600000
A26: Depriciation rate
A27: Franchise cost | B27: 0.05
A28: Furniture | B28: 0.1
A29: Development cost | B29: 0.1
A30: Interiors cost | B30: 0.1
A31: Civil work | B31: 0.1
A32: Machinery | B32: 0.15
A34: Land size | B34: 3000 | C34: Sq.Ft.
A35: Building | B35: 24 | C35: Sq.Ft.
A36: Kitchen are | B36: 7.2 | C36: Sq.Ft.
A37: Store room | B37: 2.4 | C37: Sq.Ft.
A38: Washroom | B38: 0.72 | C38: Sq.Ft.
A39: Reception area | B39: 0.48 | C39: Sq.Ft.
A40: Serving are | B40: 13.2 | C40: Sq.Ft.
A41: Total Area | B41: 2400 | C41: Sq.Ft.
A42: Average table size | B42: 4 | C42: people
A43: Area per table | B43: 50 | C43: Sq.Ft.
A44: Total no. of tables | B44: 26 | C44: tables
...

Sheet Revenue
A1: Particulars | C1: 0 | D1: 1 | E1: 2 | F1: 3 | G1: 4 | H1: 5
A2: Year | C2: =Input!B2 -> 45748 | D2: =EOMONTH(C2,11) -> 46112 | E2: =EOMONTH(D2,12) -> 46477 | F2: =EOMONTH(E2,12) -> 46843 | G2: =EOMONTH(F2,12) -> 47208 | H2: =EOMONTH(G2,12) -> 47573
A3: Total No. Of operation days | C3: =IF(C2>Input!$B$15,MIN(C$2-Input!$B$15+1,Input!$B$16),0) -> 0 | D3: =IF(D2>Input!$B$15,MIN(D$2-Input!$B$15+1,Input!$B$16),0) -> 365 | E3: =IF(E2>Input!$B$15,MIN(E$2-Input!$B$15+1,Input!$B$16),0) -> 365 | F3: =IF(F2>Input!$B$15,MIN(F$2-Input!$B$15+1,Input!$B$16),0) -> 365 | G3: =IF(G2>Input!$B$15,MIN(G$2-Input!$B$15+1,Input!$B$16),0) -> 365 | H3: =IF(H2>Input!$B$15,MIN(H$2-Input!$B$15+1,Input!$B$16),0) -> 365
A4: Weekdays | C4: =IF(C$2>Input!$B$15,NETWORKDAYS(B2,C2),0) -> 0 | D4: =IF(D$2>Input!$B$15,NETWORKDAYS(C2,D2),0) -> 261 | E4: =IF(E$2>Input!$B$15,NETWORKDAYS(D2,E2),0) -> 262 | F4: =IF(F$2>Input!$B$15,NETWORKDAYS(E2,F2),0) -> 263 | G4: =IF(G$2>Input!$B$15,NETWORKDAYS(F2,G2),0) -> 261 | H4: =IF(H$2>Input!$B$15,NETWORKDAYS(G2,H2),0) -> 260
A5: Weekends | C5: =IFERROR(C3-C4,0) -> 0 | D5: =IFERROR(D3-D4,0) -> 104 | E5: =IFERROR(E3-E4,0) -> 103 | F5: =IFERROR(F3-F4,0) -> 102 | G5: =IFERROR(G3-G4,0) -> 104 | H5: =IFERROR(H3-H4,0) -> 105
A7: Occupancy
A8: Weekdays | C8: =IF(Revenue!C$2>Input!$B$15,MIN(MAX(Input!A54,B8+Input!$B$55),Input!$B$56),0) -> 0 | D8: =IF(Revenue!D$2>Input!$B$15,MIN(MAX(Input!B54,C8+Input!$B$55),Input!$B$56),0) -> 0.38 | E8: =IF(Revenue!E$2>Input!$B$15,MIN(MAX(Input!C54,D8+Input!$B$55),Input!$B$56),0) -> 0.42 | F8: =IF(Revenue!F$2>Input!$B$15,MIN(MAX(Input!D54,E8+Input!$B$55),Input!$B$56),0) -> 0.46 | G8: =IF(Revenue!G$2>Input!$B$15,MIN(MAX(Input!E54,F8+Input!$B$55),Input!$B$56),0) -> 0.5 | H8: =IF(Revenue!H$2>Input!$B$15,MIN(MAX(Input!F54,G8+Input!$B$55),Input!$B$56),0) -> 0.5
A9: Weekends | C9: =IF(Revenue!C$2>Input!A15,MIN(MAX(Input!A57,Revenue!B9+Input!$B$58),Input!$B$59),0) -> 0 | D9: =IF(Revenue!D$2>Input!B15,MIN(MAX(Input!B57,Revenue!C9+Input!$B$58),Input!$B$59),0) -> 0.45 | E9: =IF(Revenue!E$2>Input!C15,MIN(MAX(Input!C57,Revenue!D9+Input!$B$58),Input!$B$59),0) -> 0.5 | F9: =IF(Revenue!F$2>Input!D15,MIN(MAX(Input!D57,Revenue!E9+Input!$B$58),Input!$B$59),0) -> 0.55 | G9: =IF(Revenue!G$2>Input!E15,MIN(MAX(Input!E57,Revenue!F9+Input!$B$58),Input!$B$59),0) -> 0.6 | H9: =IF(Revenue!H$2>Input!F15,MIN(MAX(Input!F57,Revenue!G9+Input!$B$58),Input!$B$59),0) -> 0.6
A11: Total capacity | C11: =IF(C2>Input!$B$15,Input!$B$45,0) -> 0 | D11: =IF(D2>Input!$B$15,Input!$B$45,0) -> 104 | E11: =IF(E2>Input!$B$15,Input!$B$45,0) -> 104 | F11: =IF(F2>Input!$B$15,Input!$B$45,0) -> 104 | G11: =IF(G2>Input!$B$15,Input!$B$45,0) -> 104 | H11: =IF(H2>Input!$B$15,Input!$B$45,0) -> 104
A13: Total No. of rounds | C13: =IF(C2>Input!$B$15,Input!$B$49,0) -> 0 | D13: =IF(D2>Input!$B$15,Input!$B$49,0) -> 14 | E13: =IF(E2>Input!$B$15,Input!$B$49,0) -> 14 | F13: =IF(F2>Input!$B$15,Input!$B$49,0) -> 14 | G13: =IF(G2>Input!$B$15,Input!$B$49,0) -> 14 | H13: =IF(H2>Input!$B$15,Input!$B$49,0) -> 14
A15: Total No. of customers per day
A16: Weekdays | C16: =$D$11*C8*$D$13 -> 0 | D16: =$D$11*D8*$D$13 -> 553.28 | E16: =$D$11*E8*$D$13 -> 611.52 | F16: =$D$11*F8*$D$13 -> 669.76 | G16: =$D$11*G8*$D$13 -> 728 | H16: =$D$11*H8*$D$13 -> 728
A17: Weekends | C17: =$D$11*C9*$D$13 -> 0 | D17: =$D$11*D9*$D$13 -> 655.2 | E17: =$D$11*E9*$D$13 -> 728 | F17: =$D$11*F9*$D$13 -> 800.8 | G17: =$D$11*G9*$D$13 -> 873.6 | H17: =$D$11*H9*$D$13 -> 873.6
A19: APC | C19: =IF(C$2>=Input!$B$15,MAX(Input!$B$51,Revenue!B19*(1+Input!$B$52),)*0) -> 0 | D19: =IF(D$2>Input!C15,MAX(Input!$B$51,Revenue!C19*(1+Input!$B$52),0)) -> 235 | E19: =IF(E$2>Input!D15,MAX(Input!$B$51,Revenue!D19*(1+Input!$B$52),0)) -> 246.75 | F19: =IF(F$2>Input!E15,MAX(Input!$B$51,Revenue!E19*(1+Input!$B$52),0)) -> 259.0875 | G19: =IF(G$2>Input!F15,MAX(Input!$B$51,Revenue!F19*(1+Input!$B$52),0)) -> 272.04188 | H19: =IF(H$2>Input!G15,MAX(Input!$B$51,Revenue!G19*(1+Input!$B$52),0)) -> 285.64397
A21: Revenue per day
A22: Outlet
A23: Weekdays | C23: =C16*C19 -> 0 | D23: =D16*D19 -> 130020.8 | E23: =E16*E19 -> 150892.56 | F23: =F16*F19 -> 173526.44 | G23: =G16*G19 -> 198046.49 | H23: =H16*H19 -> 207948.81
A24: Weekends | C24: =C17*C19 -> 0 | D24: =D17*D19 -> 153972 | E24: =E17*E19 -> 179634 | F24: =F17*F19 -> 207477.27 | G24: =G17*G19 -> 237655.78 | H24: =H17*H19 -> 249538.57
A25: Online
A26: Weekdays | C26: =C23*Input!$B$62 -> 0 | D26: =D23*Input!$B$62 -> 26004.16 | E26: =E23*Input!$B$62 -> 30178.512 | F26: =F23*Input!$B$62 -> 34705.289 | G26: =G23*Input!$B$62 -> 39609.297 | H26: =H23*Input!$B$62 -> 41589.762
A27: Weekends | C27: =C24*Input!$B$62 -> 0 | D27: =D24*Input!$B$62 -> 30794.4 | E27: =E24*Input!$B$62 -> 35926.8 | F27: =F24*Input!$B$62 -> 41495.454 | G27: =G24*Input!$B$62 -> 47531.156 | H27: =H24*Input!$B$62 -> 49907.714
A28: Total revenue per day
A29: Weekdays | C29: =C23+C26 -> 0 | D29: =D23+D26 -> 156024.96 | E29: =E23+E26 -> 181071.07 | F29: =F23+F26 -> 208231.73 | G29: =G23+G26 -> 237655.78 | H29: =H23+H26 -> 249538.57
A30: Weekends | C30: =C24+C27 -> 0 | D30: =D24+D27 -> 184766.4 | E30: =E24+E27 -> 215560.8 | F30: =F24+F27 -> 248972.72 | G30: =G24+G27 -> 285186.94 | H30: =H24+H27 -> 299446.29
A32: Annual Revenue
A33: Outlet
A34: Weekdays | C34: =C23*C4 -> 0 | D34: =D23*D4 -> 33935429 | E34: =E23*E4 -> 39533851 | F34: =F23*F4 -> 45637455 | G34: =G23*G4 -> 51690133 | H34: =H23*H4 -> 54066690
A35: Weekends | C35: =C24*C5 -> 0 | D35: =D24*D5 -> 16013088 | E35: =E24*E5 -> 18502302 | F35: =F24*F5 -> 21162682 | G35: =G24*G5 -> 24716201 | H35: =H24*H5 -> 26201550
A36: Total Outlet Sales | C36: =C25*C6 -> 0 | D36: =D34+D35 -> 49948517 | E36: =E34+E35 -> 58036153 | F36: =F34+F35 -> 66800136 | G36: =G34+G35 -> 76406334 | H36: =H34+H35 -> 80268240
A37: Online | C37: =C26*C7 -> 0
A38: Weekdays | C38: =C27*C8 -> 0 | D38: =D26*D4 -> 6787085.8 | E38: =E26*E4 -> 7906770.1 | F38: =F26*F4 -> 9127491 | G38: =G26*G4 -> 10338027 | H38: =H26*H4 -> 10813338
A39: Weekends | C39: =C28*C9 -> 0 | D39: =D27*D5 -> 3202617.6 | E39: =E27*E5 -> 3700460.4 | F39: =F27*F5 -> 4232536.3 | G39: =G27*G5 -> 4943240.3 | H39: =H27*H5 -> 5240310
A40: Total Online Sales | C40: =C29*C10 -> 0 | D40: =D38+D39 -> 9989703.4 | E40: =E38+E39 -> 11607231 | F40: =F38+F39 -> 13360027 | G40: =G38+G39 -> 15281267 | H40: =H38+H39 -> 16053648
A42: Total Sales | D42: =D36+D40 -> 59938220 | E42: =E36+E40 -> 69643383 | F42: =F36+F40 -> 80160164 | G42: =G36+G40 -> 91687601 | H42: =H36+H40 -> 96321888
A43: Sales growth rate% | E43: =E42/D42-1 -> 0.16191944 | F43: =F42/E42-1 -> 0.15100904 | G43: =G42/F42-1 -> 0.14380506 | H43: =H42/G42-1 -> 0.050544323
A45: End of Sheet

Sheet Fixed Assets
A1: Particulars | C1: 0 | D1: 1 | E1: 2 | F1: 3 | G1: 4 | H1: 5
A2: Year | C2: =Input!B2 -> 45748 | D2: =EOMONTH(C2,11) -> 46112 | E2: =EOMONTH(D2,12) -> 46477 | F2: =EOMONTH(E2,12) -> 46843 | G2: =EOMONTH(F2,12) -> 47208 | H2: =EOMONTH(G2,12) -> 47573
A3: Franchise
A4: Opening Balance | C4: =B7 -> 0 | D4: =C7 -> 0 | E4: =D7 -> 3000000 | F4: =E7 -> 3000000 | G4: =F7 -> 3000000 | H4: =G7 -> 3000000
A5: Add : Purchases | D5: =Input!B18 -> 3000000
A6: Less : Sales | C6: 0 | D6: 0 | E6: 0 | F6: 0 | G6: 0 | H6: 0
A7: Gross Block | C7: =C4+C5-C6 -> 0 | D7: =D4+D5-D6 -> 3000000 | E7: =E4+E5-E6 -> 3000000 | F7: =F4+F5-F6 -> 3000000 | G7: =G4+G5-G6 -> 3000000 | H7: =H4+H5-H6 -> 3000000
A8: Less : Accumulated Depriciation | D8: =D7*Input!$B$27+C8 -> 150000 | E8: =E7*Input!$B$27+D8 -> 300000 | F8: =F7*Input!$B$27+E8 -> 450000 | G8: =G7*Input!$B$27+F8 -> 600000 | H8: =H7*Input!$B$27+G8 -> 750000
A9: Net Block | C9: =C7-C8 -> 0 | D9: =D7-D8 -> 2850000 | E9: =E7-E8 -> 2700000 | F9: =F7-F8 -> 2550000 | G9: =G7-G8 -> 2400000 | H9: =H7-H8 -> 2250000
A11: Depriciation on Franchise | D11: =D8-C8 -> 150000 | E11: =E8-D8 -> 150000 | F11: =F8-E8 -> 150000 | G11: =G8-F8 -> 150000 | H11: =H8-G8 -> 150000
A13: Furniture
A14: Opening Balance | C14: =B17 -> 0 | D14: =C17 -> 0 | E14: =D17 -> 1100000 | F14: =E17 -> 1100000 | G14: =F17 -> 1100000 | H14: =G17 -> 1100000
A15: Add : Purchases | D15: =Input!B19 -> 1100000
A16: Less : Sales | C16: 0 | D16: 0 | E16: 0 | F16: 0 | G16: 0 | H16: 0
A17: Gross Block | C17: =C14+C15-C16 -> 0 | D17: =D14+D15-D16 -> 1100000 | E17: =E14+E15-E16 -> 1100000 | F17: =F14+F15-F16 -> 1100000 | G17: =G14+G15-G16 -> 1100000 | H17: =H14+H15-H16 -> 1100000
A18: Less : Accumulated Depriciation | D18: =D17*Input!$B$28+'Fixed Assets'!C18 -> 110000 | E18: =E17*Input!$B$28+'Fixed Assets'!D18 -> 220000 | F18: =F17*Input!$B$28+'Fixed Assets'!E18 -> 330000 | G18: =G17*Input!$B$28+'Fixed Assets'!F18 -> 440000 | H18: =H17*Input!$B$28+'Fixed Assets'!G18 -> 550000
A19: Net Block | C19: =C17-C18 -> 0 | D19: =D17-D18 -> 990000 | E19: =E17-E18 -> 880000 | F19: =F17-F18 -> 770000 | G19: =G17-G18 -> 660000 | H19: =H17-H18 -> 550000
A21: Depriciation on Furniture | D21: =D18-C18 -> 110000 | E21: =E18-D18 -> 110000 | F21: =F18-E18 -> 110000 | G21: =G18-F18 -> 110000 | H21: =H18-G18 -> 110000
A23: Development
A24: Opening Balance | C24: =B27 -> 0 | D24: =C27 -> 0 | E24: =D27 -> 5000000 | F24: =E27 -> 5000000 | G24: =F27 -> 5000000 | H24: =G27 -> 5000000
A25: Add : Purchases | D25: =Input!B20 -> 5000000
A26: Less : Sales | C26: 0 | D26: 0 | E26: 0 | F26: 0 | G26: 0 | H26: 0
A27: Gross Block | C27: =C24+C25-C26 -> 0 | D27: =D24+D25-D26 -> 5000000 | E27: =E24+E25-E26 -> 5000000 | F27: =F24+F25-F26 -> 5000000 | G27: =G24+G25-G26 -> 5000000 | H27: =H24+H25-H26 -> 5000000
A28: Less : Accumulated Depriciation | D28: =D27*Input!$B$29+'Fixed Assets'!C28 -> 500000 | E28: =E27*Input!$B$29+'Fixed Assets'!D28 -> 1000000 | F28: =F27*Input!$B$29+'Fixed Assets'!E28 -> 1500000 | G28: =G27*Input!$B$29+'Fixed Assets'!F28 -> 2000000 | H28: =H27*Input!$B$29+'Fixed Assets'!G28 -> 2500000
A29: Net Block | C29: =C27-C28 -> 0 | D29: =D27-D28 -> 4500000 | E29: =E27-E28 -> 4000000 | F29: =F27-F28 -> 3500000 | G29: =G27-G28 -> 3000000 | H29: =H27-H28 -> 2500000
A31: Depriciation on Development | D31: =D28-C28 -> 500000 | E31: =E28-D28 -> 500000 | F31: =F28-E28 -> 500000 | G31: =G28-F28 -> 500000 | H31: =H28-G28 -> 500000
A33: Interior
A34: Opening Balance | C34: =B37 -> 0 | D34: =C37 -> 0 | E34: =D37 -> 2000000 | F34: =E37 -> 2000000 | G34: =F37 -> 2000000 | H34: =G37 -> 2000000
A35: Add : Purchases | D35: =Input!B21 -> 2000000
A36: Less : Sales | C36: 0 | D36: 0 | E36: 0 | F36: 0 | G36: 0 | H36: 0
A37: Gross Block | C37: =C34+C35-C36 -> 0 | D37: =D34+D35-D36 -> 2000000 | E37: =E34+E35-E36 -> 2000000 | F37: =F34+F35-F36 -> 2000000 | G37: =G34+G35-G36 -> 2000000 | H37: =H34+H35-H36 -> 2000000
A38: Less : Accumulated Depriciation | D38: =D37*Input!$B$30+'Fixed Assets'!C38 -> 200000 | E38: =E37*Input!$B$30+'Fixed Assets'!D38 -> 400000 | F38: =F37*Input!$B$30+'Fixed Assets'!E38 -> 600000 | G38: =G37*Input!$B$30+'Fixed Assets'!F38 -> 800000 | H38: =H37*Input!$B$30+'Fixed Assets'!G38 -> 1000000
A39: Net Block | C39: =C37-C38 -> 0 | D39: =D37-D38 -> 1800000 | E39: =E37-E38 -> 1600000 | F39: =F37-F38 -> 1400000 | G39: =G37-G38 -> 1200000 | H39: =H37-H38 -> 1000000
A41: Depriciation on Interior | D41: =D38-C38 -> 200000 | E41: =E38-D38 -> 200000 | F41: =F38-E38 -> 200000 | G41: =G38-F38 -> 200000 | H41: =H38-G38 -> 200000
A43: civil work
A44: Opening Balance | C44: =B47 -> 0 | D44: =C47 -> 0 | E44: =D47 -> 1000000 | F44: =E47 -> 1000000 | G44: =F47 -> 1000000 | H44: =G47 -> 1000000
A45: Add : Purchases | D45: =Input!B22 -> 1000000
A46: Less : Sales | C46: 0 | D46: 0 | E46: 0 | F46: 0 | G46: 0 | H46: 0
A47: Gross Block | C47: =C44+C45-C46 -> 0 | D47: =D44+D45-D46 -> 1000000 | E47: =E44+E45-E46 -> 1000000 | F47: =F44+F45-F46 -> 1000000 | G47: =G44+G45-G46 -> 1000000 | H47: =H44+H45-H46 -> 1000000
A48: Less : Accumulated Depriciation | D48: =D47*Input!$B$31+'Fixed Assets'!C48 -> 100000 | E48: =E47*Input!$B$31+'Fixed Assets'!D48 -> 200000 | F48: =F47*Input!$B$31+'Fixed Assets'!E48 -> 300000 | G48: =G47*Input!$B$31+'Fixed Assets'!F48 -> 400000 | H48: =H47*Input!$B$31+'Fixed Assets'!G48 -> 500000
...

Sheet P&L
A1: Particulars | C1: 0 | D1: 1 | E1: 2 | F1: 3 | G1: 4 | H1: 5
A2: Year | C2: =Input!B2 -> 45748 | D2: =EOMONTH(C2,11) -> 46112 | E2: =EOMONTH(D2,12) -> 46477 | F2: =EOMONTH(E2,12) -> 46843 | G2: =EOMONTH(F2,12) -> 47208 | H2: =EOMONTH(G2,12) -> 47573
A3: Sales
A4: Outlet | D4: =Revenue!D36 -> 49948517 | E4: =Revenue!E36 -> 58036153 | F4: =Revenue!F36 -> 66800136 | G4: =Revenue!G36 -> 76406334 | H4: =Revenue!H36 -> 80268240
A5: Online | D5: =Revenue!D40 -> 9989703.4 | E5: =Revenue!E40 -> 11607231 | F5: =Revenue!F40 -> 13360027 | G5: =Revenue!G40 -> 15281267 | H5: =Revenue!H40 -> 16053648
A6: Total Sales | D6: =SUM(D4:D5) -> 59938220 | E6: =SUM(E4:E5) -> 69643383 | F6: =SUM(F4:F5) -> 80160164 | G6: =SUM(G4:G5) -> 91687601 | H6: =SUM(H4:H5) -> 96321888
A8: Less : Direct Cost
A9: COGS | D9: =D6*Input!$B$66 -> 21577759 | E9: =E6*Input!$B$66 -> 25071618 | F9: =F6*Input!$B$66 -> 28857659 | G9: =G6*Input!$B$66 -> 33007536 | H9: =H6*Input!$B$66 -> 34675880
A10: Commission to food aggregator | D10: =D5*Input!$B$68 -> 399588.13 | E10: =E5*Input!$B$68 -> 464289.22 | F10: =F5*Input!$B$68 -> 534401.09 | G10: =G5*Input!$B$68 -> 611250.67 | H10: =H5*Input!$B$68 -> 642145.92
A11: Total Direct Cost | D11: =SUM(D9:D10) -> 21977347 | E11: =SUM(E9:E10) -> 25535907 | F11: =SUM(F9:F10) -> 29392060 | G11: =SUM(G9:G10) -> 33618787 | H11: =SUM(H9:H10) -> 35318026
A12: Gross Profit | D12: =D6-D11 -> 37960873 | E12: =E6-E11 -> 44107476 | F12: =F6-F11 -> 50768104 | G12: =G6-G11 -> 58068814 | H12: =H6-H11 -> 61003863
A13: Gross Margin% | D13: =D12/D6 -> 0.63333333 | E13: =E12/E6 -> 0.63333333 | F13: =F12/F6 -> 0.63333333 | G13: =G12/G6 -> 0.63333333 | H13: =H12/H6 -> 0.63333333
A15: Less : Indirect cost
A16: Royalty | D16: =D6*Input!$B$65 -> 4795057.6 | E16: =E6*Input!$B$65 -> 5571470.7 | F16: =F6*Input!$B$65 -> 6412813.1 | G16: =G6*Input!$B$65 -> 7335008.1 | H16: =H6*Input!$B$65 -> 7705751.1
A17: Advertisement cost | D17: =D6*Input!$B$67 -> 3596293.2 | E17: =E6*Input!$B$67 -> 4178603 | F17: =F6*Input!$B$67 -> 4809609.8 | G17: =G6*Input!$B$67 -> 5501256 | H17: =H6*Input!$B$67 -> 5779313.3
A18: Maintenance | D18: =IF(D$2>Input!$B$15,MAX(C18*(1+Input!$B96),Input!$B91),0) -> 2400000 | E18: =IF(E$2>Input!$B$15,MAX(D18*(1+Input!$B96),Input!$B91),0) -> 2520000 | F18: =IF(F$2>Input!$B$15,MAX(E18*(1+Input!$B96),Input!$B91),0) -> 2646000 | G18: =IF(G$2>Input!$B$15,MAX(F18*(1+Input!$B96),Input!$B91),0) -> 2778300 | H18: =IF(H$2>Input!$B$15,MAX(G18*(1+Input!$B96),Input!$B91),0) -> 2917215
A19: Electricity and water | D19: =IF(D$2>Input!$B$15,MAX(C19*(1+Input!$B97),Input!$B92),0) -> 1200000 | E19: =IF(E$2>Input!$B$15,MAX(D19*(1+Input!$B97),Input!$B92),0) -> 1224000 | F19: =IF(F$2>Input!$B$15,MAX(E19*(1+Input!$B97),Input!$B92),0) -> 1248480 | G19: =IF(G$2>Input!$B$15,MAX(F19*(1+Input!$B97),Input!$B92),0) -> 1273449.6 | H19: =IF(H$2>Input!$B$15,MAX(G19*(1+Input!$B97),Input!$B92),0) -> 1298918.6
A20: Misc. Expenses | D20: =IF(D$2>Input!$B$15,MAX(C20*(1+Input!$B98),Input!$B93),0) -> 600000 | E20: =IF(E$2>Input!$B$15,MAX(D20*(1+Input!$B98),Input!$B93),0) -> 618000 | F20: =IF(F$2>Input!$B$15,MAX(E20*(1+Input!$B98),Input!$B93),0) -> 636540 | G20: =IF(G$2>Input!$B$15,MAX(F20*(1+Input!$B98),Input!$B93),0) -> 655636.2 | H20: =IF(H$2>Input!$B$15,MAX(G20*(1+Input!$B98),Input!$B93),0) -> 675305.29
A21: Salary
A22: Cleaner | D22: =IF(D$2>Input!$B$15,Input!D72*Input!D84*Input!$B$89) -> 960000 | E22: =IF(E$2>Input!$B$15,Input!E72*Input!E84*Input!$B$89) -> 1512000 | F22: =IF(F$2>Input!$B$15,Input!F72*Input!F84*Input!$B$89) -> 2116800 | G22: =IF(G$2>Input!$B$15,Input!G72*Input!G84*Input!$B$89) -> 2778300 | H22: =IF(H$2>Input!$B$15,Input!H72*Input!H84*Input!$B$89) -> 2917220
A23: Support staff | D23: =IF(D$2>Input!$B$15,Input!D73*Input!D85*Input!$B$89) -> 11520000 | E23: =IF(E$2>Input!$B$15,Input!E73*Input!E85*Input!$B$89) -> 15408000 | F23: =IF(F$2>Input!$B$15,Input!F73*Input!F85*Input!$B$89) -> 16486560 | G23: =IF(G$2>Input!$B$15,Input!G73*Input!G85*Input!$B$89) -> 21168720 | H23: =IF(H$2>Input!$B$15,Input!H73*Input!H85*Input!$B$89) -> 22650576
A24: Accountant | D24: =IF(D$2>Input!$B$15,Input!D74*Input!D86*Input!$B$89) -> 1440000 | E24: =IF(E$2>Input!$B$15,Input!E74*Input!E86*Input!$B$89) -> 1540800 | F24: =IF(F$2>Input!$B$15,Input!F74*Input!F86*Input!$B$89) -> 1648656 | G24: =IF(G$2>Input!$B$15,Input!G74*Input!G86*Input!$B$89) -> 1764062 | H24: =IF(H$2>Input!$B$15,Input!H74*Input!H86*Input!$B$89) -> 1887546
A25: Manager | D25: =IF(D$2>Input!$B$15,Input!D75*Input!D87*Input!$B$89) -> 2000000 | E25: =IF(E$2>Input!$B$15,Input!E75*Input!E87*Input!$B$89) -> 2140000 | F25: =IF(F$2>Input!$B$15,Input!F75*Input!F87*Input!$B$89) -> 2289800 | G25: =IF(G$2>Input!$B$15,Input!G75*Input!G87*Input!$B$89) -> 2450086 | H25: =IF(H$2>Input!$B$15,Input!H75*Input!H87*Input!$B$89) -> 2621592
A26: Total Indirect expense | D26: =SUM(D16:D25) -> 28511351 | E26: =SUM(E16:E25) -> 34712874 | F26: =SUM(F16:F25) -> 38295259 | G26: =SUM(G16:G25) -> 45704818 | H26: =SUM(H16:H25) -> 48453437
A28: EBITDA | D28: =D12-D26 -> 9449521.9 | E28: =E12-E26 -> 9394602.4 | F28: =F12-F26 -> 12472845 | G28: =G12-G26 -> 12363996 | H28: =H12-H26 -> 12550425
A29: EBITDA Margin % | D29: =D28/D6 -> 0.15765436 | E29: =E28/E6 -> 0.13489584 | F29: =F28/F6 -> 0.15559904 | G29: =G28/G6 -> 0.13484916 | H29: =H28/H6 -> 0.13029671
A31: Depriciation
A32: Depriciation on Franchise | D32: 150000 | E32: 150000 | F32: 150000 | G32: 150000 | H32: 150000
A33: Depriciation on Furniture | D33: 110000 | E33: 110000 | F33: 110000 | G33: 110000 | H33: 110000
A34: Depriciation on Development | D34: 500000 | E34: 500000 | F34: 500000 | G34: 500000 | H34: 500000
A35: Depriciation on Interior | D35: 200000 | E35: 200000 | F35: 200000 | G35: 200000 | H35: 200000
A36: Depriciation on civil work | D36: 100000 | E36: 100000 | F36: 100000 | G36: 100000 | H36: 100000
A37: Depriciation on Machinery | D37: 525000 | E37: 525000 | F37: 525000 | G37: 525000 | H37: 525000
A39: EBIT | D39: =D28-SUM(D32:D37) -> 7864521.9 | E39: =E28-SUM(E32:E37) -> 7809602.4 | F39: =F28-SUM(F32:F37) -> 10887845 | G39: =G28-SUM(G32:G37) -> 10778996 | H39: =H28-SUM(H32:H37) -> 10965425
A40: Less: Interest
A42: PBT | D42: =D39-D40 -> 7864521.9 | E42: =E39-E40 -> 7809602.4 | F42: =F39-F40 -> 10887845 | G42: =G39-G40 -> 10778996 | H42: =H39-H40 -> 10965425
A43: Less: Income Tax | D43: =D42*Input!$B$12 -> 1979500.2 | E43: =E42*Input!$B$12 -> 1965676.9 | F43: =F42*Input!$B$12 -> 2740470.5 | G43: =G42*Input!$B$12 -> 2713073.3 | H43: =H42*Input!$B$12 -> 2759997.6
A45: PAT | D45: =D42-D43 -> 5885021.8 | E45: =E42-E43 -> 5843925.5 | F45: =F42-F43 -> 8147374.2 | G45: =G42-G43 -> 8065922.6 | H45: =H42-H43 -> 8205427.8
A46: Net profit Margin % | D46: =D45/D6 -> 0.098184794 | E46: =E45/E6 -> 0.083912142 | F46: =F45/F6 -> 0.10163869 | G46: =G45/G6 -> 0.087971793 | H46: =H45/H6 -> 0.085187572
A48: End of Sheet

Sheet Balance Sheet
A1: Particulars | C1: 0 | D1: 1 | E1: 2 | F1: 3 | G1: 4 | H1: 5
A2: Year | C2: =Input!B2 -> 45748 | D2: =EOMONTH(C2,11) -> 46112 | E2: =EOMONTH(D2,12) -> 46477 | F2: =EOMONTH(E2,12) -> 46843 | G2: =EOMONTH(F2,12) -> 47208 | H2: =EOMONTH(G2,12) -> 47573
A3: Equity and Liabilities
A4: Equity
A5: Equity share capital | D5: =Input!B24 -> 15600000 | E5: =D5 -> 15600000 | F5: =E5 -> 15600000 | G5: =F5 -> 15600000 | H5: =G5 -> 15600000
A6: Reserves and surplus | D6: ='P&L'!D45 -> 5885021.8 | E6: ='P&L'!E45+D6 -> 11728947 | F6: ='P&L'!F45+E6 -> 19876321 | G6: ='P&L'!G45+F6 -> 27942244 | H6: ='P&L'!H45+G6 -> 36147672
A7: Total Equity | D7: =SUM(D5:D6) -> 21485022 | E7: =SUM(E5:E6) -> 27328947 | F7: =SUM(F5:F6) -> 35476321 | G7: =SUM(G5:G6) -> 43542244 | H7: =SUM(H5:H6) -> 51747672
A9: Liabilities
A10: Non-current Liabilty
A11: Debt | D11: 0 | E11: 0 | F11: 0 | G11: 0 | H11: 0
A13: Current Liability
A14: Outstanding expenses | D14: ='P&L'!D26/365*Input!$B$100 -> 2343398.7 | E14: ='P&L'!E26/365*Input!$B$100 -> 2853112.9 | F14: ='P&L'!F26/365*Input!$B$100 -> 3147555.5 | G14: ='P&L'!G26/365*Input!$B$100 -> 3756560.4 | H14: ='P&L'!H26/365*Input!$B$100 -> 3982474.3
A15: Total of Liabilities | D15: =D11+D14 -> 2343398.7 | E15: =E11+E14 -> 2853112.9 | F15: =F11+F14 -> 3147555.5 | G15: =G11+G14 -> 3756560.4 | H15: =H11+H14 -> 3982474.3
A16: Total | D16: =D7+D15 -> 23828420 | E16: =E7+E15 -> 30182060 | F16: =F7+F15 -> 38623877 | G16: =G7+G15 -> 47298804 | H16: =H7+H15 -> 55730146
A18: Assets
A19: Non-current Assets
A20: Fixed assets
A21: Gross Block | D21: =SUMIF('Fixed Assets'!$A$1:$H$61,'Balance Sheet'!$A21,'Fixed Assets'!D1:D$61) -> 15600000 | E21: =SUMIF('Fixed Assets'!$A$1:$H$61,'Balance Sheet'!$A21,'Fixed Assets'!E1:E$61) -> 15600000 | F21: =SUMIF('Fixed Assets'!$A$1:$H$61,'Balance Sheet'!$A21,'Fixed Assets'!F1:F$61) -> 15600000 | G21: =SUMIF('Fixed Assets'!$A$1:$H$61,'Balance Sheet'!$A21,'Fixed Assets'!G1:G$61) -> 15600000 | H21: =SUMIF('Fixed Assets'!$A$1:$H$61,'Balance Sheet'!$A21,'Fixed Assets'!H1:H$61) -> 15600000
A22: Less : Accumulated Depriciation | D22: =SUMIF('Fixed Assets'!$A$1:$H$61,'Balance Sheet'!$A22,'Fixed Assets'!D$1:D$61) -> 1585000 | E22: =SUMIF('Fixed Assets'!$A$1:$H$61,'Balance Sheet'!$A22,'Fixed Assets'!E$1:E$61) -> 3170000 | F22: =SUMIF('Fixed Assets'!$A$1:$H$61,'Balance Sheet'!$A22,'Fixed Assets'!F$1:F$61) -> 4755000 | G22: =SUMIF('Fixed Assets'!$A$1:$H$61,'Balance Sheet'!$A22,'Fixed Assets'!G$1:G$61) -> 6340000 | H22: =SUMIF('Fixed Assets'!$A$1:$H$61,'Balance Sheet'!$A22,'Fixed Assets'!H$1:H$61) -> 7925000
A23: Net Block | D23: =D21-D22 -> 14015000 | E23: =E21-E22 -> 12430000 | F23: =F21-F22 -> 10845000 | G23: =G21-G22 -> 9260000 | H23: =H21-H22 -> 7675000
A25: Current Assets
A26: Stock | D26: ='P&L'!D9/365*Input!$B$101 -> 413820.04 | E26: ='P&L'!E9/365*Input!$B$101 -> 480825.55 | F26: ='P&L'!F9/365*Input!$B$101 -> 553434.55 | G26: ='P&L'!G9/365*Input!$B$101 -> 633021.24 | H26: ='P&L'!H9/365*Input!$B$101 -> 665016.87
A27: Cash and Bank | D27: =Cashflow!D27 -> 9399600.4 | E27: =Cashflow!E27 -> 17271235 | F27: =Cashflow!F27 -> 27225442 | G27: =Cashflow!G27 -> 37405783 | H27: =Cashflow!H27 -> 47390129
A28: Total | D28: =D23+D26+D27 -> 23828420 | E28: =E23+E26+E27 -> 30182060 | F28: =F23+F26+F27 -> 38623877 | G28: =G23+G26+G27 -> 47298804 | H28: =H23+H26+H27 -> 55730146
A29: Check | C29: =C28-C16 -> 0 | D29: =D28-D16 -> 0 | E29: =E28-E16 -> 0 | F29: =F28-F16 -> 0 | G29: =G28-G16 -> 0 | H29: =H28-H16 -> 0
A31: End of Sheet

Sheet Cashflow
A1: Particulars | C1: 0 | D1: 1 | E1: 2 | F1: 3 | G1: 4 | H1: 5
A2: Year | C2: =Input!B2 -> 45748 | D2: =EOMONTH(C2,11) -> 46112 | E2: =EOMONTH(D2,12) -> 46477 | F2: =EOMONTH(E2,12) -> 46843 | G2: =EOMONTH(F2,12) -> 47208 | H2: =EOMONTH(G2,12) -> 47573
A3: Operating activity
A4: PAT | D4: ='P&L'!D45 -> 5885021.8 | E4: ='P&L'!E45 -> 5843925.5 | F4: ='P&L'!F45 -> 8147374.2 | G4: ='P&L'!G45 -> 8065922.6 | H4: ='P&L'!H45 -> 8205427.8
A5: Add: Non cash items
A6: Depriciation | D6: =SUM('P&L'!D32:D37) -> 1585000 | E6: =SUM('P&L'!E32:E37) -> 1585000 | F6: =SUM('P&L'!F32:F37) -> 1585000 | G6: =SUM('P&L'!G32:G37) -> 1585000 | H6: =SUM('P&L'!H32:H37) -> 1585000
A7: CFO before working capital changes | D7: =D4+D6 -> 7470021.8 | E7: =E4+E6 -> 7428925.5 | F7: =F4+F6 -> 9732374.2 | G7: =G4+G6 -> 9650922.6 | H7: =H4+H6 -> 9790427.8
A8: Less:Increase in Current Asset/Decrease in current Liability | D8: =-('Balance Sheet'!D26-'Balance Sheet'!C26) -> -413820.04 | E8: =-('Balance Sheet'!E26-'Balance Sheet'!D26) -> -67005.51 | F8: =-('Balance Sheet'!F26-'Balance Sheet'!E26) -> -72609.004 | G8: =-('Balance Sheet'!G26-'Balance Sheet'!F26) -> -79586.689 | H8: =-('Balance Sheet'!H26-'Balance Sheet'!G26) -> -31995.63
A9: Add:Decrease in Current Asset/Increase in current Liability | D9: =('Balance Sheet'!D14-'Balance Sheet'!C14) -> 2343398.7 | E9: =('Balance Sheet'!E14-'Balance Sheet'!D14) -> 509714.21 | F9: =('Balance Sheet'!F14-'Balance Sheet'!E14) -> 294442.62 | G9: =('Balance Sheet'!G14-'Balance Sheet'!F14) -> 609004.85 | H9: =('Balance Sheet'!H14-'Balance Sheet'!G14) -> 225913.92
A10: Total Cashflow from Operation | D10: =D7+D8+D9 -> 9399600.4 | E10: =E7+E8+E9 -> 7871634.2 | F10: =F7+F8+F9 -> 9954207.8 | G10: =G7+G8+G9 -> 10180341 | H10: =H7+H8+H9 -> 9984346.1
A12: Investing activity
A13: Purchase of assets
A14: Franchise cost | D14: =-Input!B18 -> -3000000
A15: Furniture | D15: =-Input!B19 -> -1100000
A16: Development Cost | D16: =-Input!B20 -> -5000000
A17: Interiors cost | D17: =-Input!B21 -> -2000000
A18: Civil work | D18: =-Input!B22 -> -1000000
A19: Machinery | D19: =-Input!B23 -> -3500000
A20: Total Cashflow from Investing | D20: =-Input!B24 -> -15600000 | E20: =-Input!C24 -> 0 | F20: =-Input!D24 -> 0 | G20: =-Input!E24 -> 0 | H20: =-Input!F24 -> 0
A22: Financing activity
A23: Equity share capital | D23: ='Balance Sheet'!D5-'Balance Sheet'!C5 -> 15600000 | E23: ='Balance Sheet'!E5-'Balance Sheet'!D5 -> 0 | F23: ='Balance Sheet'!F5-'Balance Sheet'!E5 -> 0 | G23: ='Balance Sheet'!G5-'Balance Sheet'!F5 -> 0 | H23: ='Balance Sheet'!H5-'Balance Sheet'!G5 -> 0
A25: Total cash genearted during year | D25: =D23+D10+D20 -> 9399600.4 | E25: =E23+E10+E20 -> 7871634.2 | F25: =F23+F10+F20 -> 9954207.8 | G25: =G23+G10+G20 -> 10180341 | H25: =H23+H10+H20 -> 9984346.1
A26: Add: Opening balance of cash | D26: =C27 -> 0 | E26: =D27 -> 9399600.4 | F26: =E27 -> 17271235 | G26: =F27 -> 27225442 | H26: =G27 -> 37405783
A27: Closing balance | D27: =D26+D25 -> 9399600.4 | E27: =E26+E25 -> 17271235 | F27: =F26+F25 -> 27225442 | G27: =G26+G25 -> 37405783 | H27: =H26+H25 -> 47390129
A29: End of Sheet

Sheet Rentals
A1: Particulars | C1: 0 | D1: 1 | E1: 2 | F1: 3 | G1: 4 | H1: 5
A2: Year | C2: =Input!B2 -> 45748 | D2: =EOMONTH(C2,11) -> 46112 | E2: =EOMONTH(D2,12) -> 46477 | F2: =EOMONTH(E2,12) -> 46843 | G2: =EOMONTH(F2,12) -> 47208 | H2: =EOMONTH(G2,12) -> 47573
A3: Opportunity Cost (Purchase of land) | C3: =-Input!B4 -> -45000000
A4: Rental Income | C4: =IF(B$2>=Input!$B$2,MAX((Input!$B$4*Input!$B$7),B4*(1+Input!$B$8)),0) -> 0 | D4: =IF(C$2>=Input!$B$2,MAX((Input!$B$4*Input!$B$7),C4*(1+Input!$B$8)),0) -> 2250000 | E4: =MAX((Input!$B$4*Input!$B$7),D4*(1+Input!$B$8)) -> 2430000 | F4: =MAX((Input!$B$4*Input!$B$7),E4*(1+Input!$B$8)) -> 2624400 | G4: =MAX((Input!$B$4*Input!$B$7),F4*(1+Input!$B$8)) -> 2834352 | H4: =MAX((Input!$B$4*Input!$B$7),G4*(1+Input!$B$8)) -> 3061100.2
A5: Interest Income | D5: =IF(D$2>=Input!$B$2,Input!$B$10*Input!$B$11,0) -> 300000 | E5: =IF(E$2>=Input!$B$2,Input!$B$10*Input!$B$11,0) -> 300000 | F5: =IF(F$2>=Input!$B$2,Input!$B$10*Input!$B$11,0) -> 300000 | G5: =IF(G$2>=Input!$B$2,Input!$B$10*Input!$B$11,0) -> 300000 | H5: =IF(H$2>=Input!$B$2,Input!$B$10*Input!$B$11,0) -> 300000
A6: Non Refundable deposit | C6: =Input!B10 -> 5000000
A7: Total Income before tax | C7: =SUM(C4:C6) -> 5000000 | D7: =SUM(D4:D6) -> 2550000 | E7: =SUM(E4:E6) -> 2730000 | F7: =SUM(F4:F6) -> 2924400 | G7: =SUM(G4:G6) -> 3134352 | H7: =SUM(H4:H6) -> 3361100.2
A8: Less: Income tax | D8: =D7*Input!$B$12+(Rentals!C6*Input!$B$12) -> 1900335 | E8: =E7*Input!$B$12+(Rentals!D6*Input!$B$12) -> 687141 | F8: =F7*Input!$B$12+(Rentals!E6*Input!$B$12) -> 736071.48 | G8: =G7*Input!$B$12+(Rentals!F6*Input!$B$12) -> 788916.4 | H8: =H7*Input!$B$12+(Rentals!G6*Input!$B$12) -> 845988.91
A9: Total Income After tax | C9: =C7-C8 -> 5000000 | D9: =D7-D8 -> 649665 | E9: =E7-E8 -> 2042859 | F9: =F7-F8 -> 2188328.5 | G9: =G7-G8 -> 2345435.6 | H9: =H7-H8 -> 2515111.2
A10: Terminal Value | H10: =Input!B4*(1+Input!B9)^Rentals!H1 -> 82909583
A11: FCFE | C11: =C9+C10+C3 -> -40000000 | D11: =D9+D10+D3 -> 649665 | E11: =E9+E10+E3 -> 2042859 | F11: =F9+F10+F3 -> 2188328.5 | G11: =G9+G10+G3 -> 2345435.6 | H11: =H9+H10+H3 -> 85424694
A13: IRR | C13: =XIRR(C11:H11,C2:H2) -> 0.19159403
A15: End of Sheet

Sheet Mc Donalds Franchise
A1: Particulars | C1: 0 | D1: 1 | E1: 2 | F1: 3 | G1: 4 | H1: 5
A2: Year | C2: =Input!B2 -> 45748 | D2: =EOMONTH(C2,11) -> 46112 | E2: =EOMONTH(D2,12) -> 46477 | F2: =EOMONTH(E2,12) -> 46843 | G2: =EOMONTH(F2,12) -> 47208 | H2: =EOMONTH(G2,12) -> 47573
A3: Opportunity cost(Purchase of land) | C3: =-Input!B4 -> -45000000
A4: EBIT | D4: ='P&L'!D39 -> 7864521.9 | E4: ='P&L'!E39 -> 7809602.4 | F4: ='P&L'!F39 -> 10887845 | G4: ='P&L'!G39 -> 10778996 | H4: ='P&L'!H39 -> 10965425
A5: Less: Taxes | D5: =D4*Input!$B$12 -> 1979500.2 | E5: =E4*Input!$B$12 -> 1965676.9 | F5: =F4*Input!$B$12 -> 2740470.5 | G5: =G4*Input!$B$12 -> 2713073.3 | H5: =H4*Input!$B$12 -> 2759997.6
A6: NOPAT | D6: =D4-D5 -> 5885021.8 | E6: =E4-E5 -> 5843925.5 | F6: =F4-F5 -> 8147374.2 | G6: =G4-G5 -> 8065922.6 | H6: =H4-H5 -> 8205427.8
A7: Add: Depriciation | D7: =Cashflow!D6 -> 1585000 | E7: =Cashflow!E6 -> 1585000 | F7: =Cashflow!F6 -> 1585000 | G7: =Cashflow!G6 -> 1585000 | H7: =Cashflow!H6 -> 1585000
A8: Add/Less: Changes in working cpaital | D8: =SUM(Cashflow!D8:D9) -> 1929578.7 | E8: =SUM(Cashflow!E8:E9) -> 442708.7 | F8: =SUM(Cashflow!F8:F9) -> 221833.62 | G8: =SUM(Cashflow!G8:G9) -> 529418.16 | H8: =SUM(Cashflow!H8:H9) -> 193918.29
A9: Less: CAPEX | C9: =-Input!B24 -> -15600000
A10: FCFF/FCFE | C10: =C9+C8+C7+C6+C3 -> -60600000 | D10: =D9+D8+D7+D6 -> 9399600.4 | E10: =E9+E8+E7+E6 -> 7871634.2 | F10: =F9+F8+F7+F6 -> 9954207.8 | G10: =G9+G8+G7+G6 -> 10180341 | H10: =H9+H8+H7+H6 -> 9984346.1
A11: Terminal Value | H11: =H10*(1+Input!B104)/(Input!B103-Input!B104) -> 80642796
A12: FCFF/FCFE | C12: =C10+C11 -> -60600000 | D12: =D10+D11 -> 9399600.4 | E12: =E10+E11 -> 7871634.2 | F12: =F10+F11 -> 9954207.8 | G12: =G10+G11 -> 10180341 | H12: =H10+H11 -> 90627142
A14: IRR | C14: =XIRR(C12:H12,C2:H2) -> 0.19897841
A16: End of Sheet

Sheet Output
A1: Particulars | C1: 0 | D1: 1 | E1: 2 | F1: 3 | G1: 4 | H1: 5
A2: Year | C2: =Input!B2 -> 45748 | D2: =EOMONTH(C2,11) -> 46112 | E2: =EOMONTH(D2,12) -> 46477 | F2: =EOMONTH(E2,12) -> 46843 | G2: =EOMONTH(F2,12) -> 47208 | H2: =EOMONTH(G2,12) -> 47573
A4: Mc Donald's IRR | C4: ='Mc Donalds Franchise'!C14 -> 0.19897841
A5: Rental IRR | C5: =Rentals!C13 -> 0.19159403
A7: Decision | C7: =IF(C4>C5,"Go for McDonald's","GoforRental") -> Go for McDonald's
A9: End of Sheet
